[10/Jul/2016 05:59:37] ERROR [django.request:256] Internal Server Error: /para/
Traceback (most recent call last):
  File "/opt/Python-2.7/lib/python2.7/site-packages/django/core/handlers/base.py", line 119, in get_response
    resolver_match = resolver.resolve(request.path_info)
  File "/opt/Python-2.7/lib/python2.7/site-packages/django/core/urlresolvers.py", line 368, in resolve
    sub_match = pattern.resolve(new_path)
  File "/opt/Python-2.7/lib/python2.7/site-packages/django/core/urlresolvers.py", line 240, in resolve
    return ResolverMatch(self.callback, args, kwargs, self.name)
  File "/opt/Python-2.7/lib/python2.7/site-packages/django/core/urlresolvers.py", line 247, in callback
    self._callback = get_callable(self._callback_str)
  File "/opt/Python-2.7/lib/python2.7/site-packages/django/utils/lru_cache.py", line 101, in wrapper
    result = user_function(*args, **kwds)
  File "/opt/Python-2.7/lib/python2.7/site-packages/django/core/urlresolvers.py", line 106, in get_callable
    mod = import_module(mod_name)
  File "/opt/Python-2.7/lib/python2.7/importlib/__init__.py", line 37, in import_module
    __import__(name)
  File "/root/recognize/restful/api/views.py", line 19, in <module>
    from server import recognize
  File "../server.py", line 6, in <module>
    from img_process import convert_img_to_binary
  File "../img_process.py", line 70
    self.logger.debug('--filename--%s' % (filename))
    ^
IndentationError: unexpected indent
[10/Jul/2016 05:59:37] ERROR [django.request:256] Internal Server Error: /para/
Traceback (most recent call last):
  File "/opt/Python-2.7/lib/python2.7/site-packages/django/core/handlers/base.py", line 119, in get_response
    resolver_match = resolver.resolve(request.path_info)
  File "/opt/Python-2.7/lib/python2.7/site-packages/django/core/urlresolvers.py", line 368, in resolve
    sub_match = pattern.resolve(new_path)
  File "/opt/Python-2.7/lib/python2.7/site-packages/django/core/urlresolvers.py", line 240, in resolve
    return ResolverMatch(self.callback, args, kwargs, self.name)
  File "/opt/Python-2.7/lib/python2.7/site-packages/django/core/urlresolvers.py", line 247, in callback
    self._callback = get_callable(self._callback_str)
  File "/opt/Python-2.7/lib/python2.7/site-packages/django/utils/lru_cache.py", line 101, in wrapper
    result = user_function(*args, **kwds)
  File "/opt/Python-2.7/lib/python2.7/site-packages/django/core/urlresolvers.py", line 106, in get_callable
    mod = import_module(mod_name)
  File "/opt/Python-2.7/lib/python2.7/importlib/__init__.py", line 37, in import_module
    __import__(name)
  File "/root/recognize/restful/api/views.py", line 19, in <module>
    from server import recognize
  File "../server.py", line 6, in <module>
    from img_process import convert_img_to_binary
  File "../img_process.py", line 70
    self.logger.debug('--filename--%s' % (filename))
    ^
IndentationError: unexpected indent
[10/Jul/2016 05:59:37] ERROR [django.request:256] Internal Server Error: /para/
Traceback (most recent call last):
  File "/opt/Python-2.7/lib/python2.7/site-packages/django/core/handlers/base.py", line 119, in get_response
    resolver_match = resolver.resolve(request.path_info)
  File "/opt/Python-2.7/lib/python2.7/site-packages/django/core/urlresolvers.py", line 368, in resolve
    sub_match = pattern.resolve(new_path)
  File "/opt/Python-2.7/lib/python2.7/site-packages/django/core/urlresolvers.py", line 240, in resolve
    return ResolverMatch(self.callback, args, kwargs, self.name)
  File "/opt/Python-2.7/lib/python2.7/site-packages/django/core/urlresolvers.py", line 247, in callback
    self._callback = get_callable(self._callback_str)
  File "/opt/Python-2.7/lib/python2.7/site-packages/django/utils/lru_cache.py", line 101, in wrapper
    result = user_function(*args, **kwds)
  File "/opt/Python-2.7/lib/python2.7/site-packages/django/core/urlresolvers.py", line 106, in get_callable
    mod = import_module(mod_name)
  File "/opt/Python-2.7/lib/python2.7/importlib/__init__.py", line 37, in import_module
    __import__(name)
  File "/root/recognize/restful/api/views.py", line 19, in <module>
    from server import recognize
  File "../server.py", line 6, in <module>
    from img_process import convert_img_to_binary
  File "../img_process.py", line 70
    self.logger.debug('--filename--%s' % (filename))
    ^
IndentationError: unexpected indent
[10/Jul/2016 05:59:38] ERROR [django.request:256] Internal Server Error: /para/
Traceback (most recent call last):
  File "/opt/Python-2.7/lib/python2.7/site-packages/django/core/handlers/base.py", line 119, in get_response
    resolver_match = resolver.resolve(request.path_info)
  File "/opt/Python-2.7/lib/python2.7/site-packages/django/core/urlresolvers.py", line 368, in resolve
    sub_match = pattern.resolve(new_path)
  File "/opt/Python-2.7/lib/python2.7/site-packages/django/core/urlresolvers.py", line 240, in resolve
    return ResolverMatch(self.callback, args, kwargs, self.name)
  File "/opt/Python-2.7/lib/python2.7/site-packages/django/core/urlresolvers.py", line 247, in callback
    self._callback = get_callable(self._callback_str)
  File "/opt/Python-2.7/lib/python2.7/site-packages/django/utils/lru_cache.py", line 101, in wrapper
    result = user_function(*args, **kwds)
  File "/opt/Python-2.7/lib/python2.7/site-packages/django/core/urlresolvers.py", line 106, in get_callable
    mod = import_module(mod_name)
  File "/opt/Python-2.7/lib/python2.7/importlib/__init__.py", line 37, in import_module
    __import__(name)
  File "/root/recognize/restful/api/views.py", line 19, in <module>
    from server import recognize
  File "../server.py", line 6, in <module>
    from img_process import convert_img_to_binary
  File "../img_process.py", line 70
    self.logger.debug('--filename--%s' % (filename))
    ^
IndentationError: unexpected indent
[10/Jul/2016 05:59:47] ERROR [django.request:256] Internal Server Error: /para/
Traceback (most recent call last):
  File "/opt/Python-2.7/lib/python2.7/site-packages/django/core/handlers/base.py", line 119, in get_response
    resolver_match = resolver.resolve(request.path_info)
  File "/opt/Python-2.7/lib/python2.7/site-packages/django/core/urlresolvers.py", line 368, in resolve
    sub_match = pattern.resolve(new_path)
  File "/opt/Python-2.7/lib/python2.7/site-packages/django/core/urlresolvers.py", line 240, in resolve
    return ResolverMatch(self.callback, args, kwargs, self.name)
  File "/opt/Python-2.7/lib/python2.7/site-packages/django/core/urlresolvers.py", line 247, in callback
    self._callback = get_callable(self._callback_str)
  File "/opt/Python-2.7/lib/python2.7/site-packages/django/utils/lru_cache.py", line 101, in wrapper
    result = user_function(*args, **kwds)
  File "/opt/Python-2.7/lib/python2.7/site-packages/django/core/urlresolvers.py", line 106, in get_callable
    mod = import_module(mod_name)
  File "/opt/Python-2.7/lib/python2.7/importlib/__init__.py", line 37, in import_module
    __import__(name)
  File "/root/recognize/restful/api/views.py", line 19, in <module>
    from server import recognize
  File "../server.py", line 6, in <module>
    from img_process import convert_img_to_binary
  File "../img_process.py", line 70
    self.logger.debug('--filename--%s' % (filename))
    ^
IndentationError: unexpected indent
[10/Jul/2016 05:59:47] ERROR [django.request:256] Internal Server Error: /para/
Traceback (most recent call last):
  File "/opt/Python-2.7/lib/python2.7/site-packages/django/core/handlers/base.py", line 119, in get_response
    resolver_match = resolver.resolve(request.path_info)
  File "/opt/Python-2.7/lib/python2.7/site-packages/django/core/urlresolvers.py", line 368, in resolve
    sub_match = pattern.resolve(new_path)
  File "/opt/Python-2.7/lib/python2.7/site-packages/django/core/urlresolvers.py", line 240, in resolve
    return ResolverMatch(self.callback, args, kwargs, self.name)
  File "/opt/Python-2.7/lib/python2.7/site-packages/django/core/urlresolvers.py", line 247, in callback
    self._callback = get_callable(self._callback_str)
  File "/opt/Python-2.7/lib/python2.7/site-packages/django/utils/lru_cache.py", line 101, in wrapper
    result = user_function(*args, **kwds)
  File "/opt/Python-2.7/lib/python2.7/site-packages/django/core/urlresolvers.py", line 106, in get_callable
    mod = import_module(mod_name)
  File "/opt/Python-2.7/lib/python2.7/importlib/__init__.py", line 37, in import_module
    __import__(name)
  File "/root/recognize/restful/api/views.py", line 19, in <module>
    from server import recognize
  File "../server.py", line 6, in <module>
    from img_process import convert_img_to_binary
  File "../img_process.py", line 70
    self.logger.debug('--filename--%s' % (filename))
    ^
IndentationError: unexpected indent
[10/Jul/2016 05:59:48] ERROR [django.request:256] Internal Server Error: /para/
Traceback (most recent call last):
  File "/opt/Python-2.7/lib/python2.7/site-packages/django/core/handlers/base.py", line 119, in get_response
    resolver_match = resolver.resolve(request.path_info)
  File "/opt/Python-2.7/lib/python2.7/site-packages/django/core/urlresolvers.py", line 368, in resolve
    sub_match = pattern.resolve(new_path)
  File "/opt/Python-2.7/lib/python2.7/site-packages/django/core/urlresolvers.py", line 240, in resolve
    return ResolverMatch(self.callback, args, kwargs, self.name)
  File "/opt/Python-2.7/lib/python2.7/site-packages/django/core/urlresolvers.py", line 247, in callback
    self._callback = get_callable(self._callback_str)
  File "/opt/Python-2.7/lib/python2.7/site-packages/django/utils/lru_cache.py", line 101, in wrapper
    result = user_function(*args, **kwds)
  File "/opt/Python-2.7/lib/python2.7/site-packages/django/core/urlresolvers.py", line 106, in get_callable
    mod = import_module(mod_name)
  File "/opt/Python-2.7/lib/python2.7/importlib/__init__.py", line 37, in import_module
    __import__(name)
  File "/root/recognize/restful/api/views.py", line 19, in <module>
    from server import recognize
  File "../server.py", line 6, in <module>
    from img_process import convert_img_to_binary
  File "../img_process.py", line 70
    self.logger.debug('--filename--%s' % (filename))
    ^
IndentationError: unexpected indent
[10/Jul/2016 05:59:48] ERROR [django.request:256] Internal Server Error: /para/
Traceback (most recent call last):
  File "/opt/Python-2.7/lib/python2.7/site-packages/django/core/handlers/base.py", line 119, in get_response
    resolver_match = resolver.resolve(request.path_info)
  File "/opt/Python-2.7/lib/python2.7/site-packages/django/core/urlresolvers.py", line 368, in resolve
    sub_match = pattern.resolve(new_path)
  File "/opt/Python-2.7/lib/python2.7/site-packages/django/core/urlresolvers.py", line 240, in resolve
    return ResolverMatch(self.callback, args, kwargs, self.name)
  File "/opt/Python-2.7/lib/python2.7/site-packages/django/core/urlresolvers.py", line 247, in callback
    self._callback = get_callable(self._callback_str)
  File "/opt/Python-2.7/lib/python2.7/site-packages/django/utils/lru_cache.py", line 101, in wrapper
    result = user_function(*args, **kwds)
  File "/opt/Python-2.7/lib/python2.7/site-packages/django/core/urlresolvers.py", line 106, in get_callable
    mod = import_module(mod_name)
  File "/opt/Python-2.7/lib/python2.7/importlib/__init__.py", line 37, in import_module
    __import__(name)
  File "/root/recognize/restful/api/views.py", line 19, in <module>
    from server import recognize
  File "../server.py", line 6, in <module>
    from img_process import convert_img_to_binary
  File "../img_process.py", line 70
    self.logger.debug('--filename--%s' % (filename))
    ^
IndentationError: unexpected indent
[10/Jul/2016 06:01:48] ERROR [django.request:256] Internal Server Error: /para/
Traceback (most recent call last):
  File "/opt/Python-2.7/lib/python2.7/site-packages/django/core/handlers/base.py", line 119, in get_response
    resolver_match = resolver.resolve(request.path_info)
  File "/opt/Python-2.7/lib/python2.7/site-packages/django/core/urlresolvers.py", line 368, in resolve
    sub_match = pattern.resolve(new_path)
  File "/opt/Python-2.7/lib/python2.7/site-packages/django/core/urlresolvers.py", line 240, in resolve
    return ResolverMatch(self.callback, args, kwargs, self.name)
  File "/opt/Python-2.7/lib/python2.7/site-packages/django/core/urlresolvers.py", line 247, in callback
    self._callback = get_callable(self._callback_str)
  File "/opt/Python-2.7/lib/python2.7/site-packages/django/utils/lru_cache.py", line 101, in wrapper
    result = user_function(*args, **kwds)
  File "/opt/Python-2.7/lib/python2.7/site-packages/django/core/urlresolvers.py", line 106, in get_callable
    mod = import_module(mod_name)
  File "/opt/Python-2.7/lib/python2.7/importlib/__init__.py", line 37, in import_module
    __import__(name)
  File "/root/recognize/restful/api/views.py", line 19, in <module>
    from server import recognize
  File "../server.py", line 6, in <module>
    from img_process import convert_img_to_binary
  File "../img_process.py", line 70
    logger.debug('--filename--%s' % (filename))
    ^
IndentationError: unexpected indent
[10/Jul/2016 06:01:49] ERROR [django.request:256] Internal Server Error: /para/
Traceback (most recent call last):
  File "/opt/Python-2.7/lib/python2.7/site-packages/django/core/handlers/base.py", line 119, in get_response
    resolver_match = resolver.resolve(request.path_info)
  File "/opt/Python-2.7/lib/python2.7/site-packages/django/core/urlresolvers.py", line 368, in resolve
    sub_match = pattern.resolve(new_path)
  File "/opt/Python-2.7/lib/python2.7/site-packages/django/core/urlresolvers.py", line 240, in resolve
    return ResolverMatch(self.callback, args, kwargs, self.name)
  File "/opt/Python-2.7/lib/python2.7/site-packages/django/core/urlresolvers.py", line 247, in callback
    self._callback = get_callable(self._callback_str)
  File "/opt/Python-2.7/lib/python2.7/site-packages/django/utils/lru_cache.py", line 101, in wrapper
    result = user_function(*args, **kwds)
  File "/opt/Python-2.7/lib/python2.7/site-packages/django/core/urlresolvers.py", line 106, in get_callable
    mod = import_module(mod_name)
  File "/opt/Python-2.7/lib/python2.7/importlib/__init__.py", line 37, in import_module
    __import__(name)
  File "/root/recognize/restful/api/views.py", line 19, in <module>
    from server import recognize
  File "../server.py", line 6, in <module>
    from img_process import convert_img_to_binary
  File "../img_process.py", line 70
    logger.debug('--filename--%s' % (filename))
    ^
IndentationError: unexpected indent
[10/Jul/2016 06:01:49] ERROR [django.request:256] Internal Server Error: /para/
Traceback (most recent call last):
  File "/opt/Python-2.7/lib/python2.7/site-packages/django/core/handlers/base.py", line 119, in get_response
    resolver_match = resolver.resolve(request.path_info)
  File "/opt/Python-2.7/lib/python2.7/site-packages/django/core/urlresolvers.py", line 368, in resolve
    sub_match = pattern.resolve(new_path)
  File "/opt/Python-2.7/lib/python2.7/site-packages/django/core/urlresolvers.py", line 240, in resolve
    return ResolverMatch(self.callback, args, kwargs, self.name)
  File "/opt/Python-2.7/lib/python2.7/site-packages/django/core/urlresolvers.py", line 247, in callback
    self._callback = get_callable(self._callback_str)
  File "/opt/Python-2.7/lib/python2.7/site-packages/django/utils/lru_cache.py", line 101, in wrapper
    result = user_function(*args, **kwds)
  File "/opt/Python-2.7/lib/python2.7/site-packages/django/core/urlresolvers.py", line 106, in get_callable
    mod = import_module(mod_name)
  File "/opt/Python-2.7/lib/python2.7/importlib/__init__.py", line 37, in import_module
    __import__(name)
  File "/root/recognize/restful/api/views.py", line 19, in <module>
    from server import recognize
  File "../server.py", line 6, in <module>
    from img_process import convert_img_to_binary
  File "../img_process.py", line 70
    logger.debug('--filename--%s' % (filename))
    ^
IndentationError: unexpected indent
[10/Jul/2016 06:01:49] ERROR [django.request:256] Internal Server Error: /para/
Traceback (most recent call last):
  File "/opt/Python-2.7/lib/python2.7/site-packages/django/core/handlers/base.py", line 119, in get_response
    resolver_match = resolver.resolve(request.path_info)
  File "/opt/Python-2.7/lib/python2.7/site-packages/django/core/urlresolvers.py", line 368, in resolve
    sub_match = pattern.resolve(new_path)
  File "/opt/Python-2.7/lib/python2.7/site-packages/django/core/urlresolvers.py", line 240, in resolve
    return ResolverMatch(self.callback, args, kwargs, self.name)
  File "/opt/Python-2.7/lib/python2.7/site-packages/django/core/urlresolvers.py", line 247, in callback
    self._callback = get_callable(self._callback_str)
  File "/opt/Python-2.7/lib/python2.7/site-packages/django/utils/lru_cache.py", line 101, in wrapper
    result = user_function(*args, **kwds)
  File "/opt/Python-2.7/lib/python2.7/site-packages/django/core/urlresolvers.py", line 106, in get_callable
    mod = import_module(mod_name)
  File "/opt/Python-2.7/lib/python2.7/importlib/__init__.py", line 37, in import_module
    __import__(name)
  File "/root/recognize/restful/api/views.py", line 19, in <module>
    from server import recognize
  File "../server.py", line 6, in <module>
    from img_process import convert_img_to_binary
  File "../img_process.py", line 70
    logger.debug('--filename--%s' % (filename))
    ^
IndentationError: unexpected indent
[10/Jul/2016 08:18:25] ERROR [django.request:256] Internal Server Error: /para/
Traceback (most recent call last):
  File "/opt/Python-2.7/lib/python2.7/site-packages/django/core/handlers/base.py", line 223, in get_response
    response = middleware_method(request, response)
  File "/opt/Python-2.7/lib/python2.7/site-packages/django/middleware/clickjacking.py", line 31, in process_response
    if response.get('X-Frame-Options', None) is not None:
AttributeError: 'str' object has no attribute 'get'
[10/Jul/2016 08:18:40] ERROR [django.request:256] Internal Server Error: /para/
Traceback (most recent call last):
  File "/opt/Python-2.7/lib/python2.7/site-packages/django/core/handlers/base.py", line 223, in get_response
    response = middleware_method(request, response)
  File "/opt/Python-2.7/lib/python2.7/site-packages/django/middleware/clickjacking.py", line 31, in process_response
    if response.get('X-Frame-Options', None) is not None:
AttributeError: 'str' object has no attribute 'get'
[10/Jul/2016 08:41:18] ERROR [django.request:256] Internal Server Error: /para/
Traceback (most recent call last):
  File "/opt/Python-2.7/lib/python2.7/site-packages/django/core/handlers/base.py", line 223, in get_response
    response = middleware_method(request, response)
  File "/opt/Python-2.7/lib/python2.7/site-packages/django/middleware/clickjacking.py", line 31, in process_response
    if response.get('X-Frame-Options', None) is not None:
AttributeError: 'str' object has no attribute 'get'
[10/Jul/2016 08:55:50] ERROR [django.request:256] Internal Server Error: /para/
Traceback (most recent call last):
  File "/opt/Python-2.7/lib/python2.7/site-packages/django/core/handlers/base.py", line 223, in get_response
    response = middleware_method(request, response)
  File "/opt/Python-2.7/lib/python2.7/site-packages/django/middleware/clickjacking.py", line 31, in process_response
    if response.get('X-Frame-Options', None) is not None:
AttributeError: 'str' object has no attribute 'get'
[10/Jul/2016 08:56:16] ERROR [django.request:256] Internal Server Error: /para/
Traceback (most recent call last):
  File "/opt/Python-2.7/lib/python2.7/site-packages/django/core/handlers/base.py", line 223, in get_response
    response = middleware_method(request, response)
  File "/opt/Python-2.7/lib/python2.7/site-packages/django/middleware/clickjacking.py", line 31, in process_response
    if response.get('X-Frame-Options', None) is not None:
AttributeError: 'str' object has no attribute 'get'
[10/Jul/2016 08:56:37] ERROR [django.request:256] Internal Server Error: /para/
Traceback (most recent call last):
  File "/opt/Python-2.7/lib/python2.7/site-packages/django/core/handlers/base.py", line 223, in get_response
    response = middleware_method(request, response)
  File "/opt/Python-2.7/lib/python2.7/site-packages/django/middleware/clickjacking.py", line 31, in process_response
    if response.get('X-Frame-Options', None) is not None:
AttributeError: 'str' object has no attribute 'get'
[10/Jul/2016 08:57:28] ERROR [django.request:256] Internal Server Error: /para/
Traceback (most recent call last):
  File "/opt/Python-2.7/lib/python2.7/site-packages/django/core/handlers/base.py", line 223, in get_response
    response = middleware_method(request, response)
  File "/opt/Python-2.7/lib/python2.7/site-packages/django/middleware/clickjacking.py", line 31, in process_response
    if response.get('X-Frame-Options', None) is not None:
AttributeError: 'str' object has no attribute 'get'
